<?xml version="1.0" encoding="utf-8"?>

<robot
  name="1dof_planar">
  <link name="world" />

  <joint name="world_to_base_link=" type="fixed">
    <parent link="world"/>
    <child link="base_link"/>
  </joint>
  <link
    name="base_link" type="fixed">
    <inertial>
      <origin
        xyz="0.0030299 2.6279E-13 0.02912"
        rpy="0 0 0" />
      <mass
        value="0.10159" />
      <inertia
        ixx="2.636E-05"
        ixy="-1.007E-16"
        ixz="-2.3835E-06"
        iyy="1.8042E-05"
        iyz="-4.6617E-09"
        izz="1.8795E-05" />
    </inertial>
    <visual>
      <origin
        xyz="0 0 0"
        rpy="0 0 0" />
      <geometry>
        <mesh
          filename="/home/pasquale/Desktop/thesis/base_link.stl" />
      </geometry>
      <material
        name="">
        <color
          rgba="0.96078 1 0 1" />
      </material>
    </visual>
    <collision>
      <origin
        xyz="0 0 0"
        rpy="0 0 0" />
      <geometry>
        <mesh
          filename="/home/pasquale/Desktop/thesis/base_link.stl" />
      </geometry>
    </collision>
  </link>
  <link
    name="link1">
    <inertial>
      <origin
        xyz="0.0086107 2.1727E-06 0.036012"
        rpy="0 0 0" />
      <mass
        value="0.26703" />
      <inertia
        ixx="0.00040827"
        ixy="1.2675E-09"
        ixz="1.8738E-05"
        iyy="0.00038791"
        iyz="3.5443E-08"
        izz="3.6421E-05" />
    </inertial>
    <visual>
      <origin
        xyz="0 0 0"
        rpy="0 0 0" />
      <geometry>
        <mesh
          filename="/home/pasquale/Desktop/thesis/thesis/stl/link1.stl" />
      </geometry>
      <material
        name="">
        <color
          rgba="0.64706 0.61961 0.58824 1" />
      </material>
    </visual>
    <collision>
      <origin
        xyz="0 0 0"
        rpy="0 0 0" />
      <geometry>
        <mesh
          filename="/home/pasquale/Desktop/thesis/thesis/stl/link1.stl" />
      </geometry>
    </collision>
  </link>
  <joint
    name="joint1"
    type="revolute">
    <origin
      xyz="0.0060872 0 0.035"
      rpy="3.1416 0 0" />
    <parent
      link="base_link" />
    <child
      link="link1" />
    <axis
      xyz="1 0 0" />
    <limit
      effort="10"
      velocity="50" />
    <dynamics
      damping="0.05" />
  </joint>
</robot>
